Workbook

Sheet Raw_Data
A1: PR 2 ANALYZER — Raw Sales Data (500 Rows)
A2: Order ID | B2: Customer Name | C2: Region | D2: Product | E2: Category | F2: Sales | G2: Profit | H2: Discount | I2: Quantity | J2: Order Date | K2: Month | L2: Year
A3: ORD-1001 | B3: Grace Taylor | C3: North | D3: Speaker | E3: Audio | F3: 3659.46 | G3: 789.67 | H3: 0.25 | I3: 11 | J3: 44695 | K3: 5 | L3: 2022
A4: ORD-1002 | B4: David Smith | C4: West | D4: Keyboard | E4: Accessories | F4: 4778.32 | G4: 1393.01 | H4: 0.15 | I4: 6 | J4: 45350 | K4: 2 | L4: 2024
A5: ORD-1003 | B5: Rachel Davis | C5: Central | D5: Printer | E5: Office | F5: 1154.77 | G5: 285.27 | H5: 0.15 | I5: 18 | J5: 45311 | K5: 1 | L5: 2024
A6: ORD-1004 | B6: Iris Davis | C6: West | D6: Tablet | E6: Electronics | F6: 736.97 | G6: 200.26 | H6: 0.15 | I6: 10 | J6: 44569 | K6: 1 | L6: 2022
A7: ORD-1005 | B7: Bob Smith | C7: North | D7: Router | E7: Networking | F7: 3713.16 | G7: 1215.21 | H7: 0.05 | I7: 18 | J7: 44642 | K7: 3 | L7: 2022
A8: ORD-1006 | B8: Henry White | C8: Central | D8: Webcam | E8: Accessories | F8: 1472.27 | G8: 227.23 | H8: 0.25 | I8: 7 | J8: 45649 | K8: 12 | L8: 2024
A9: ORD-1007 | B9: Sam Miller | C9: East | D9: Mouse | E9: Accessories | F9: 4976.72 | G9: 886.34 | H9: 0.15 | I9: 17 | J9: 44965 | K9: 2 | L9: 2023
A10: ORD-1008 | B10: Rachel Brown | C10: North | D10: Mouse | E10: Accessories | F10: 300.96 | G10: 35.56 | H10: 0.25 | I10: 8 | J10: 44615 | K10: 2 | L10: 2022
A11: ORD-1009 | B11: Sam Jackson | C11: South | D11: Laptop | E11: Electronics | F11: 4546.02 | G11: 454.86 | H11: 0.15 | I11: 8 | J11: 45246 | K11: 11 | L11: 2023
A12: ORD-1010 | B12: Rachel Miller | C12: Central | D12: Mouse | E12: Accessories | F12: 3672.09 | G12: 672.14 | H12: 0.25 | I12: 8 | J12: 45114 | K12: 7 | L12: 2023
A13: ORD-1011 | B13: Iris Williams | C13: North | D13: Monitor | E13: Electronics | F13: 2269.05 | G13: 368.09 | H13: 0.2 | I13: 2 | J13: 45617 | K13: 11 | L13: 2024
A14: ORD-1012 | B14: Sam Miller | C14: North | D14: Monitor | E14: Electronics | F14: 3695.43 | G14: 569.3 | H14: 0.05 | I14: 7 | J14: 45509 | K14: 8 | L14: 2024
... A502: ORD-1500 | B502: Noah Taylor | C502: West | D502: Webcam | E502: Accessories | F502: 3035.8 | G502: 256.49 | H502: 0.2 | I502: 2 | J502: 44853 | K502: 10 | L502: 2022

Sheet Conditional_Formatting
A1: Conditional Formatting Analysis
A3: Customer Total Purchase Analysis | E3: Profit Heatmap
A4: Customer Name | B4: Total Sales | C4: Rank | E4: Product | F4: Avg Profit | G4: Indicator
A5: Rachel Davis | B5: 59481.52 | C5: =RANK(B5,$B$5:$B$34,0) -> 1 | E5: Headphones | F5: 548.23
A6: Sam Jackson | B6: 53000.46 | C6: =RANK(B6,$B$5:$B$34,0) -> 2 | E6: Speaker | F6: 539.74
A7: Leo Anderson | B7: 52227.11 | C7: =RANK(B7,$B$5:$B$34,0) -> 3 | E7: Keyboard | F7: 531.09
A8: David Thomas | B8: 48286.14 | C8: =RANK(B8,$B$5:$B$34,0) -> 4 | E8: Mouse | F8: 524.94
A9: Iris Williams | B9: 42300.96 | C9: =RANK(B9,$B$5:$B$34,0) -> 5 | E9: Laptop | F9: 520.15
A10: David Williams | B10: 41682.15 | C10: =RANK(B10,$B$5:$B$34,0) -> 6 | E10: Router | F10: 469.55
A11: Sam Miller | B11: 41288.74 | C11: =RANK(B11,$B$5:$B$34,0) -> 7 | E11: Tablet | F11: 467.54
A12: Grace Taylor | B12: 38642.88 | C12: =RANK(B12,$B$5:$B$34,0) -> 8 | E12: Monitor | F12: 462.76
A13: Rachel Brown | B13: 38334.22 | C13: =RANK(B13,$B$5:$B$34,0) -> 9 | E13: Webcam | F13: 451.11
A14: Carol Davis | B14: 36052.53 | C14: =RANK(B14,$B$5:$B$34,0) -> 10 | E14: Printer | F14: 442.32
A15: Sam Wilson | B15: 35837.09 | C15: =RANK(B15,$B$5:$B$34,0) -> 11
A16: Carol Johnson | B16: 35804.08 | C16: =RANK(B16,$B$5:$B$34,0) -> 12
A17: Tina Anderson | B17: 33742.39 | C17: =RANK(B17,$B$5:$B$34,0) -> 13
A18: Mia White | B18: 32301.82 | C18: =RANK(B18,$B$5:$B$34,0) -> 14
A19: Frank Jackson | B19: 30343.87 | C19: =RANK(B19,$B$5:$B$34,0) -> 15
A20: Henry White | B20: 30191.59 | C20: =RANK(B20,$B$5:$B$34,0) -> 16
A21: Bob Smith | B21: 29795.76 | C21: =RANK(B21,$B$5:$B$34,0) -> 17
A22: Grace Harris | B22: 29757.68 | C22: =RANK(B22,$B$5:$B$34,0) -> 18
A23: Tina Wilson | B23: 28083.42 | C23: =RANK(B23,$B$5:$B$34,0) -> 19
A24: Carol Miller | B24: 27454.98 | C24: =RANK(B24,$B$5:$B$34,0) -> 20
A25: Tina White | B25: 27409.14 | C25: =RANK(B25,$B$5:$B$34,0) -> 21
A26: Rachel Miller | B26: 25696.72 | C26: =RANK(B26,$B$5:$B$34,0) -> 22
... A34: Quinn Wilson | B34: 21357.79 | C34: =RANK(B34,$B$5:$B$34,0) -> 30

Sheet What_If_Analysis
A1: What-If: Discount Impact on Profit
A3: Base Assumptions
A4: Total Sales | B4: 1336008.7
A5: Base Profit | B5: 248655.73
A6: Profit Margin % | B6: 18.61
A8: Discount Scenario Analysis
A9: Discount % | B9: Sales After Disc. | C9: Projected Profit | D9: Profit Change $ | E9: Profit Change % | F9: Margin % | G9: Decision
A10: 0.05 | B10: =$B$4*(1-A10) -> 1269208.2 | C10: =B10*($B$6/100) -> 236199.65 | D10: =C10-$B$5 -> -12456.075 | E10: =(C10-$B$5)/$B$5 -> -0.050093659 | F10: =C10/B10 -> 0.1861 | G10: =IF(D10>0,"✔ Profitable","✘ Loss") -> ✘ Loss
A11: 0.1 | B11: =$B$4*(1-A11) -> 1202407.8 | C11: =B11*($B$6/100) -> 223768.09 | D11: =C11-$B$5 -> -24887.636 | E11: =(C11-$B$5)/$B$5 -> -0.10008873 | F11: =C11/B11 -> 0.1861 | G11: =IF(D11>0,"✔ Profitable","✘ Loss") -> ✘ Loss
A12: 0.15 | B12: =$B$4*(1-A12) -> 1135607.4 | C12: =B12*($B$6/100) -> 211336.53 | D12: =C12-$B$5 -> -37319.197 | E12: =(C12-$B$5)/$B$5 -> -0.1500838 | F12: =C12/B12 -> 0.1861 | G12: =IF(D12>0,"✔ Profitable","✘ Loss") -> ✘ Loss
A13: 0.2 | B13: =$B$4*(1-A13) -> 1068806.9 | C13: =B13*($B$6/100) -> 198904.97 | D13: =C13-$B$5 -> -49750.758 | E13: =(C13-$B$5)/$B$5 -> -0.20007887 | F13: =C13/B13 -> 0.1861 | G13: =IF(D13>0,"✔ Profitable","✘ Loss") -> ✘ Loss
A14: 0.25 | B14: =$B$4*(1-A14) -> 1002006.5 | C14: =B14*($B$6/100) -> 186473.41 | D14: =C14-$B$5 -> -62182.318 | E14: =(C14-$B$5)/$B$5 -> -0.25007394 | F14: =C14/B14 -> 0.1861 | G14: =IF(D14>0,"✔ Profitable","✘ Loss") -> ✘ Loss
A17: Sensitivity: Qty vs Discount
B18: 5% | C18: 10% | D18: 15% | E18: 20% | F18: 25%
A19: Qty=5 | B19: 221.85 | C19: 210.17 | D19: 198.49 | E19: 186.82 | F19: 175.14
A20: Qty=10 | B20: 443.69 | C20: 420.34 | D20: 396.99 | E20: 373.64 | F20: 350.29
A21: Qty=15 | B21: 665.54 | C21: 630.51 | D21: 595.48 | E21: 560.46 | F21: 525.43
A22: Qty=20 | B22: 887.39 | C22: 840.68 | D22: 793.98 | E22: 747.27 | F22: 700.57
A23: Qty=25 | B23: 1109.24 | C23: 1050.86 | D23: 992.47 | E23: 934.09 | F23: 875.71

Sheet Linear_Regression
A1: Linear Regression: Profit vs Sales
A3: Regression Summary | D3: Profit = 0.1829 × Sales + 8.63
A4: Metric | B4: Value
A5: R² (R-Square) | B5: 0.623855
A6: Adjusted R² | B6: 0.6231 | D6: Sales | E6: Actual Profit | F6: Predicted Profit
A7: Slope (Coefficient) | B7: 0.18289 | D7: 4546.02 | E7: 454.86 | F7: 840.05
A8: Intercept | B8: 8.6251 | D8: 3672.09 | E8: 672.14 | F8: 680.22
A9: Standard Error | B9: 191.6905 | D9: 2099.77 | E9: 382.49 | F9: 392.65
A10: T-Statistic | B10: 28.7395 | D10: 2780.65 | E10: 346.82 | F10: 517.18
A11: P-Value | B11: 0 | D11: 4091.7 | E11: 347.62 | F11: 756.96
A12: Observations | B12: 500 | D12: 3384.26 | E12: 900.02 | F12: 627.57
D13: 2749.43 | E13: 513.17 | F13: 511.47
D14: 1258.59 | E14: 190.56 | F14: 238.81
A15: Interpretation | D15: 3557.43 | E15: 429.22 | F15: 659.24
A16: For every $1 increase in Sales, Profit increases by $0.1829 | D16: 773.86 | E16: 196.01 | F16: 150.16
A17: R² = 0.6239 means 62.4% of Profit variation is explained by Sales | D17: 3030.02 | E17: 566.31 | F17: 562.79
A18: P-Value = 0.000000 — Statistically Significant (p<0.05) | D18: 3995.56 | E18: 1056.95 | F18: 739.37
D19: 1351.35 | E19: 120.37 | F19: 255.77
D20: 356.67 | E20: 83.9 | F20: 73.86
D21: 2456.05 | E21: 360.21 | F21: 457.81
D22: 3188.64 | E22: 653.93 | F22: 591.8
D23: 2850.81 | E23: 422.96 | F23: 530.01
D24: 3981.04 | E24: 1032.55 | F24: 736.72
D25: 4677.69 | E25: 1453.24 | F25: 864.13
D26: 3774.58 | E26: 593.42 | F26: 698.96
D27: 1620.19 | E27: 145.27 | F27: 304.94
D28: 4147.6 | E28: 448.04 | F28: 767.18
D29: 417.66 | E29: 69.87 | F29: 85.01
D30: 3977.49 | E30: 419.38 | F30: 736.07
... D86: 1893.91 | E86: 356.92 | F86: 355

Sheet Descriptive_Statistics
A1: Descriptive Statistics — PR 2 Analyzer
A2: Statistic | B2: Sales | C2: Profit | D2: Quantity | E2: Discount | G2: Sales Statistics Chart
A3: Count | B3: =COUNTA(Raw_Data!F3:F502) -> 500 | C3: =COUNTA(Raw_Data!G3:G502) -> 500 | D3: =COUNTA(Raw_Data!I3:I502) -> 500 | E3: =COUNTA(Raw_Data!H3:H502) -> 500 | G3: Metric | H3: Sales Value
A4: Mean | B4: =AVERAGE(Raw_Data!F3:F502) -> 2672.0174 | C4: =AVERAGE(Raw_Data!G3:G502) -> 497.31146 | D4: =AVERAGE(Raw_Data!I3:I502) -> 10.648 | E4: =AVERAGE(Raw_Data!H3:H502) -> 0.1543 | G4: Mean | H4: =B4 -> 2672.0174
A5: Median | B5: =MEDIAN(Raw_Data!F3:F502) -> 2653.005 | C5: =MEDIAN(Raw_Data!G3:G502) -> 430.89 | D5: =MEDIAN(Raw_Data!I3:I502) -> 11 | E5: =MEDIAN(Raw_Data!H3:H502) -> 0.15 | G5: Median | H5: =B5 -> 2653.005
A6: Mode | B6: =MODE(Raw_Data!F3:F502) -> 3322.59 | C6: =MODE(Raw_Data!G3:G502) -> 210.74 | D6: =MODE(Raw_Data!I3:I502) -> 12 | E6: =MODE(Raw_Data!H3:H502) -> 0.15 | G6: Mode | H6: =B6 -> 3322.59
A7: Std Deviation | B7: =STDEV(Raw_Data!F3:F502) -> 1348.4608 | C7: =STDEV(Raw_Data!G3:G502) -> 312.23917 | D7: =STDEV(Raw_Data!I3:I502) -> 5.6575712 | E7: =STDEV(Raw_Data!H3:H502) -> 0.069470586 | G7: Min | H7: =B9 -> 211.87
A8: Variance | B8: =VAR(Raw_Data!F3:F502) -> 1818346.6 | C8: =VAR(Raw_Data!G3:G502) -> 97493.299 | D8: =VAR(Raw_Data!I3:I502) -> 32.008112 | E8: =VAR(Raw_Data!H3:H502) -> 0.0048261623 | G8: Max | H8: =B10 -> 4999.56
A9: Minimum | B9: =MIN(Raw_Data!F3:F502) -> 211.87 | C9: =MIN(Raw_Data!G3:G502) -> 26.4 | D9: =MIN(Raw_Data!I3:I502) -> 1 | E9: =MIN(Raw_Data!H3:H502) -> 0.05 | G9: Std Dev | H9: =B7 -> 1348.4608
A10: Maximum | B10: =MAX(Raw_Data!F3:F502) -> 4999.56 | C10: =MAX(Raw_Data!G3:G502) -> 1453.24 | D10: =MAX(Raw_Data!I3:I502) -> 20 | E10: =MAX(Raw_Data!H3:H502) -> 0.25
A11: Range | B11: =MAX(Raw_Data!F3:F502)-MIN(Raw_Data!F3:F502) -> 4787.69 | C11: =MAX(Raw_Data!G3:G502)-MIN(Raw_Data!G3:G502) -> 1426.84 | D11: =MAX(Raw_Data!I3:I502)-MIN(Raw_Data!I3:I502) -> 19 | E11: =MAX(Raw_Data!H3:H502)-MIN(Raw_Data!H3:H502) -> 0.2
A12: Sum | B12: =SUM(Raw_Data!F3:F502) -> 1336008.7 | C12: =SUM(Raw_Data!G3:G502) -> 248655.73 | D12: =SUM(Raw_Data!I3:I502) -> 5324 | E12: =SUM(Raw_Data!H3:H502) -> 77.15
A13: Skewness | B13: =SKEW(Raw_Data!F3:F502) -> -0.054627757 | C13: =SKEW(Raw_Data!G3:G502) -> 0.76149908 | D13: =SKEW(Raw_Data!I3:I502) -> -0.03150735 | E13: =SKEW(Raw_Data!H3:H502) -> -0.041895751
A14: Kurtosis | B14: =KURT(Raw_Data!F3:F502) -> -1.1089664 | C14: =KURT(Raw_Data!G3:G502) -> 0.061836087 | D14: =KURT(Raw_Data!I3:I502) -> -1.180239 | E14: =KURT(Raw_Data!H3:H502) -> -1.2441752
A15: 25th Percentile | B15: =PERCENTILE(Raw_Data!F3:F502,0.25) -> 1577.6375 | C15: =PERCENTILE(Raw_Data!G3:G502,0.25) -> 254.275 | D15: =PERCENTILE(Raw_Data!I3:I502,0.25) -> 6 | E15: =PERCENTILE(Raw_Data!H3:H502,0.25) -> 0.1
A16: 75th Percentile | B16: =PERCENTILE(Raw_Data!F3:F502,0.75) -> 3836.0175 | C16: =PERCENTILE(Raw_Data!G3:G502,0.75) -> 703.56 | D16: =PERCENTILE(Raw_Data!I3:I502,0.75) -> 16 | E16: =PERCENTILE(Raw_Data!H3:H502,0.75) -> 0.2
A17: IQR | B17: =PERCENTILE(Raw_Data!F3:F502,0.75)-PERCENTILE(Raw_Data!F3:F502,0.25) -> 2258.38 | C17: =PERCENTILE(Raw_Data!G3:G502,0.75)-PERCENTILE(Raw_Data!G3:G502,0.25) -> 449.285 | D17: =PERCENTILE(Raw_Data!I3:I502,0.75)-PERCENTILE(Raw_Data!I3:I502,0.25) -> 10 | E17: =PERCENTILE(Raw_Data!H3:H502,0.75)-PERCENTILE(Raw_Data!H3:H502,0.25) -> 0.1
A18: Coeff of Variation | B18: =STDEV(Raw_Data!F3:F502)/AVERAGE(Raw_Data!F3:F502) -> 0.50466021 | C18: =STDEV(Raw_Data!G3:G502)/AVERAGE(Raw_Data!G3:G502) -> 0.62785436 | D18: =STDEV(Raw_Data!I3:I502)/AVERAGE(Raw_Data!I3:I502) -> 0.53132713 | E18: =STDEV(Raw_Data!H3:H502)/AVERAGE(Raw_Data!H3:H502) -> 0.45023063

Sheet Monthly_Growth
A1: Monthly Sales Growth Analysis
A2: Month | B2: 2022 | C2: 2023 | D2: 2024 | E2: YoY Growth 22→23 | F2: YoY Growth 23→24 | G2: Trend
A3: Jan | B3: 47340.49 | C3: 48891.14 | D3: 32475.93 | E3: =IF(B3>0,(C3-B3)/B3,0) -> 0.032755259 | F3: =IF(C3>0,(D3-C3)/C3,0) -> -0.3357502 | G3: =IF(F3>0,"▲ Up","▼ Down") -> ▼ Down
A4: Feb | B4: 31167.52 | C4: 33621.04 | D4: 39210.96 | E4: =IF(B4>0,(C4-B4)/B4,0) -> 0.078720412 | F4: =IF(C4>0,(D4-C4)/C4,0) -> 0.16626255 | G4: =IF(F4>0,"▲ Up","▼ Down") -> ▲ Up
A5: Mar | B5: 34374.06 | C5: 27576.1 | D5: 17192.9 | E5: =IF(B5>0,(C5-B5)/B5,0) -> -0.19776424 | F5: =IF(C5>0,(D5-C5)/C5,0) -> -0.37652895 | G5: =IF(F5>0,"▲ Up","▼ Down") -> ▼ Down
A6: Apr | B6: 53416.03 | C6: 43465.7 | D6: 25419.33 | E6: =IF(B6>0,(C6-B6)/B6,0) -> -0.18627985 | F6: =IF(C6>0,(D6-C6)/C6,0) -> -0.41518646 | G6: =IF(F6>0,"▲ Up","▼ Down") -> ▼ Down
A7: May | B7: 42433.14 | C7: 34882.81 | D7: 41888.12 | E7: =IF(B7>0,(C7-B7)/B7,0) -> -0.17793475 | F7: =IF(C7>0,(D7-C7)/C7,0) -> 0.20082413 | G7: =IF(F7>0,"▲ Up","▼ Down") -> ▲ Up
A8: Jun | B8: 17131.1 | C8: 26596.2 | D8: 31294.24 | E8: =IF(B8>0,(C8-B8)/B8,0) -> 0.55250976 | F8: =IF(C8>0,(D8-C8)/C8,0) -> 0.17664328 | G8: =IF(F8>0,"▲ Up","▼ Down") -> ▲ Up
A9: Jul | B9: 33788.67 | C9: 44800.7 | D9: 37698 | E9: =IF(B9>0,(C9-B9)/B9,0) -> 0.32590895 | F9: =IF(C9>0,(D9-C9)/C9,0) -> -0.15853993 | G9: =IF(F9>0,"▲ Up","▼ Down") -> ▼ Down
A10: Aug | B10: 41873.91 | C10: 41788.12 | D10: 39044.86 | E10: =IF(B10>0,(C10-B10)/B10,0) -> -0.0020487697 | F10: =IF(C10>0,(D10-C10)/C10,0) -> -0.065646887 | G10: =IF(F10>0,"▲ Up","▼ Down") -> ▼ Down
A11: Sep | B11: 33346.89 | C11: 32785.2 | D11: 55217.89 | E11: =IF(B11>0,(C11-B11)/B11,0) -> -0.01684385 | F11: =IF(C11>0,(D11-C11)/C11,0) -> 0.68423221 | G11: =IF(F11>0,"▲ Up","▼ Down") -> ▲ Up
A12: Oct | B12: 32266.13 | C12: 39533.8 | D12: 36740.53 | E12: =IF(B12>0,(C12-B12)/B12,0) -> 0.22524145 | F12: =IF(C12>0,(D12-C12)/C12,0) -> -0.070655237 | G12: =IF(F12>0,"▲ Up","▼ Down") -> ▼ Down
A13: Nov | B13: 50462.85 | C13: 36724.09 | D13: 34861.59 | E13: =IF(B13>0,(C13-B13)/B13,0) -> -0.27225494 | F13: =IF(C13>0,(D13-C13)/C13,0) -> -0.050716029 | G13: =IF(F13>0,"▲ Up","▼ Down") -> ▼ Down
A14: Dec | B14: 36713.99 | C14: 31185.89 | D14: 48798.76 | E14: =IF(B14>0,(C14-B14)/B14,0) -> -0.15057203 | F14: =IF(C14>0,(D14-C14)/C14,0) -> 0.56477048 | G14: =IF(F14>0,"▲ Up","▼ Down") -> ▲ Up
A15: TOTAL | B15: =SUM(B3:B14) -> 454314.78 | C15: =SUM(C3:C14) -> 441850.79 | D15: =SUM(D3:D14) -> 439843.11 | E15: =SUM(E3:E14) -> 0.21143741 | F15: =SUM(F3:F14) -> 0.31970896

Sheet Timestamp
A1: Workbook Timestamp Log
A2: Label | B2: Value | C2: Note
A3: Total Profit | B3: =SUM(Raw_Data!G3:G502) -> 248655.73 | C3: Sum formula
A4: Avg Discount | B4: =AVERAGE(Raw_Data!H3:H502) -> 0.1543 | C4: Average formula
A5: Date Range | B5: =TEXT(MIN(Raw_Data!J3:J502),"MMM-YYYY")&" to "&TEXT(MAX(Raw_Data!J3:J502),"MMM-YYYY") -> Jan-2022 to Dec-2024 | C5: MIN/MAX dates

Sheet High_Value_Customers
A1: High Value Customer Analysis
A2: Rank | B2: Customer Name | C2: Total Sales | D2: Total Profit | E2: Orders | F2: Avg Order | G2: % of Total | H2: Tier
A3: 1 | B3: Rachel Davis | C3: 59481.52 | D3: 11041.64 | E3: 22 | F3: 2703.71 | G3: 0.0445 | H3: Platinum
A4: 2 | B4: Sam Jackson | C4: 53000.46 | D4: 9140.51 | E4: 20 | F4: 2650.02 | G4: 0.0397 | H4: Platinum
A5: 3 | B5: Leo Anderson | C5: 52227.11 | D5: 10496.43 | E5: 20 | F5: 2611.36 | G5: 0.0391 | H5: Platinum
A6: 4 | B6: David Thomas | C6: 48286.14 | D6: 10033.61 | E6: 15 | F6: 3219.08 | G6: 0.0361 | H6: Gold
A7: 5 | B7: Iris Williams | C7: 42300.96 | D7: 6934.23 | E7: 18 | F7: 2350.05 | G7: 0.0317 | H7: Gold
A8: 6 | B8: David Williams | C8: 41682.15 | D8: 6652.88 | E8: 14 | F8: 2977.3 | G8: 0.0312 | H8: Gold
A9: 7 | B9: Sam Miller | C9: 41288.74 | D9: 8106.5 | E9: 12 | F9: 3440.73 | G9: 0.0309 | H9: Gold
A10: 8 | B10: Grace Taylor | C10: 38642.88 | D10: 7568.62 | E10: 14 | F10: 2760.21 | G10: 0.0289 | H10: Gold
A11: 9 | B11: Rachel Brown | C11: 38334.22 | D11: 6537.24 | E11: 15 | F11: 2555.61 | G11: 0.0287 | H11: Silver
A12: 10 | B12: Carol Davis | C12: 36052.53 | D12: 6782.54 | E12: 11 | F12: 3277.5 | G12: 0.027 | H12: Silver
A13: 11 | B13: Sam Wilson | C13: 35837.09 | D13: 7668.49 | E13: 10 | F13: 3583.71 | G13: 0.0268 | H13: Silver
A14: 12 | B14: Carol Johnson | C14: 35804.08 | D14: 6193.44 | E14: 13 | F14: 2754.16 | G14: 0.0268 | H14: Silver
... A22: 20 | B22: Carol Miller | C22: 27454.98 | D22: 5013.89 | E22: 10 | F22: 2745.5 | G22: 0.0206 | H22: Bronze
A25: Quick Lookup (XLOOKUP / INDEX-MATCH)
A26: Enter Customer Name → | B26: Rachel Davis
A27: Total Sales: | B27: =IFERROR(INDEX(C3:C22,MATCH(B26,B3:B22,0)),"Not Found") -> 59481.52
A28: Total Profit: | B28: =IFERROR(INDEX(D3:D22,MATCH(B26,B3:B22,0)),"Not Found") -> 11041.64
A29: Customer Tier: | B29: =IFERROR(INDEX(H3:H22,MATCH(B26,B3:B22,0)),"Not Found") -> Platinum

Sheet Pivot_Table
A1: Pivot Table Analysis — PR 2 Analyzer
A3: Sales by Region | F3: Sales by Product | K3: Profit by Category
A4: Region | B4: Total Sales | C4: Total Profit | D4: Total Qty | F4: Product | G4: Total Sales | H4: Total Profit | I4: Total Qty | K4: Category | L4: Total Sales | M4: Profit | N4: Qty
A5: North | B5: 288582.66 | C5: 53144.38 | D5: 1132 | F5: Headphones | G5: 180231.81 | H5: 33990.44 | I5: 626 | K5: Electronics | L5: 398012.49 | M5: 73877.08 | N5: 1582
A6: Central | B6: 274514.35 | C6: 53760 | D6: 1015 | F6: Keyboard | G6: 146359.96 | H6: 27616.73 | I6: 517 | K6: Accessories | L6: 387483.69 | M6: 73187.81 | N6: 1453
A7: East | B7: 270403.73 | C7: 46179.51 | D7: 981 | F7: Tablet | G7: 139120.17 | H7: 25714.51 | I7: 600 | K7: Audio | L7: 305162.92 | M7: 57739.21 | N7: 1129
A8: West | B8: 263318.88 | C8: 51518.26 | D8: 1165 | F8: Laptop | G8: 134914.3 | H8: 25487.27 | I8: 491 | K8: Networking | L8: 133745.83 | M8: 23947.24 | N8: 629
A9: South | B9: 239189.06 | C9: 44053.58 | D9: 1031 | F9: Router | G9: 133745.83 | H9: 23947.24 | I9: 629 | K9: Office | L9: 111603.75 | M9: 19904.39 | N9: 531
F10: Speaker | G10: 124931.11 | H10: 23748.77 | I10: 503
F11: Mouse | G11: 124883.07 | H11: 25722.07 | I11: 481
F12: Monitor | G12: 123978.02 | H12: 22675.3 | I12: 491
F13: Webcam | G13: 116240.66 | H13: 19849.01 | I13: 455
A14: Monthly Sales Trend | F14: Printer | G14: 111603.75 | H14: 19904.39 | I14: 531
A15: Month | B15: Sales | C15: Profit | D15: % Margin
A16: Jan | B16: 128707.56 | C16: 24657.56 | D16: 0.1916
A17: Feb | B17: 103999.52 | C17: 20214.17 | D17: 0.1944
A18: Mar | B18: 79143.06 | C18: 15830.01 | D18: 0.2
A19: Apr | B19: 122301.06 | C19: 21808.15 | D19: 0.1783
A20: May | B20: 119204.07 | C20: 24111.58 | D20: 0.2023
A21: Jun | B21: 75021.54 | C21: 13061.01 | D21: 0.1741
A22: Jul | B22: 116287.37 | C22: 22994.69 | D22: 0.1977
A23: Aug | B23: 122706.89 | C23: 21599.01 | D23: 0.176
A24: Sep | B24: 121349.98 | C24: 22561.1 | D24: 0.1859
A25: Oct | B25: 108540.46 | C25: 18877.34 | D25: 0.1739
A26: Nov | B26: 122048.53 | C26: 21119.44 | D26: 0.173
A27: Dec | B27: 116698.64 | C27: 21821.67 | D27: 0.187

Sheet Charts
A1: Professional Charts Gallery — PR 2 Analyzer
A3: Region | B3: Sales | C3: Profit
A4: North | B4: 288582.66 | C4: 53144.38
A5: South | B5: 239189.06 | C5: 44053.58
A6: East | B6: 270403.73 | C6: 46179.51
A7: West | B7: 263318.88 | C7: 51518.26
A8: Central | B8: 274514.35 | C8: 53760
A11: Category | B11: Sales
A12: Accessories | B12: 387483.69
A13: Audio | B13: 305162.92
A14: Office | B14: 111603.75
A15: Electronics | B15: 398012.49
A16: Networking | B16: 133745.83
A20: Month | B20: 2022 | C20: 2023 | D20: 2024
A21: Jan | B21: 47340.49 | C21: 48891.14 | D21: 32475.93
A22: Feb | B22: 31167.52 | C22: 33621.04 | D22: 39210.96
A23: Mar | B23: 34374.06 | C23: 27576.1 | D23: 17192.9
A24: Apr | B24: 53416.03 | C24: 43465.7 | D24: 25419.33
A25: May | B25: 42433.14 | C25: 34882.81 | D25: 41888.12
A26: Jun | B26: 17131.1 | C26: 26596.2 | D26: 31294.24
A27: Jul | B27: 33788.67 | C27: 44800.7 | D27: 37698
A28: Aug | B28: 41873.91 | C28: 41788.12 | D28: 39044.86
A29: Sep | B29: 33346.89 | C29: 32785.2 | D29: 55217.89
A30: Oct | B30: 32266.13 | C30: 39533.8 | D30: 36740.53
A31: Nov | B31: 50462.85 | C31: 36724.09 | D31: 34861.59
A32: Dec | B32: 36713.99 | C32: 31185.89 | D32: 48798.76
A34: Quarter | B34: Sales | C34: Profit
A35: Q1 | B35: 311850.14 | C35: 60701.74
A36: Q2 | B36: 316526.67 | C36: 58980.74
A37: Q3 | B37: 360344.24 | C37: 67154.8
A38: Q4 | B38: 347287.63 | C38: 61818.45
A42: Quantity | B42: Profit
A43: 8 | B43: 940.62
A44: 18 | B44: 803.56
A45: 14 | B45: 259.29
A46: 6 | B46: 118.2
A47: 17 | B47: 440.99
A48: 9 | B48: 666.01
A49: 12 | B49: 971.3
A50: 5 | B50: 408.82
...

Sheet Dashboard
A1: 📊 PR 2 ANALYZER — Executive Sales Dashboard
A2: Real-Time KPIs | Regional Analysis | Customer Insights | Trend Analysis
B4: 💰 | G4: 📈 | L4: 🏷️ | Q4: 📦 | V4: ⭐
B5: Total Sales | G5: Total Profit | L5: Avg Discount | Q5: Total Orders | V5: Avg Order Value
B6: =SUM(Raw_Data!F3:F502) -> 1336008.7 | G6: =SUM(Raw_Data!G3:G502) -> 248655.73 | L6: =AVERAGE(Raw_Data!H3:H502) -> 0.1543 | Q6: =COUNTA(Raw_Data!A3:A502) -> 500 | V6: =SUM(Raw_Data!F3:F502)/COUNTA(Raw_Data!A3:A502) -> 2672.0174
B10: 📊 Regional Performance | N10: 📅 Monthly Sales Trend
B11: Region | C11: Sales | D11: Profit | E11: Margin
B12: North | C12: 288583 | D12: 53144 | E12: 0.1842
B13: Central | C13: 274514 | D13: 53760 | E13: 0.1958
B14: East | C14: 270404 | D14: 46180 | E14: 0.1708
B15: West | C15: 263319 | D15: 51518 | E15: 0.1956
B16: South | C16: 239189 | D16: 44054 | E16: 0.1842
F17: 🏅 Best Region: North
F18: 🥇 Top Product: Headphones
B33: 🏆 Top 10 Customers | N33: 🥧 Category Breakdown
B34: # | C34: Customer | D34: Sales | E34: Tier
B35: 1 | C35: Rachel Davis | D35: 59482 | E35: Platinum
B36: 2 | C36: Sam Jackson | D36: 53000 | E36: Platinum
B37: 3 | C37: Leo Anderson | D37: 52227 | E37: Platinum
B38: 4 | C38: David Thomas | D38: 48286 | E38: Gold
B39: 5 | C39: Iris Williams | D39: 42301 | E39: Gold
B40: 6 | C40: David Williams | D40: 41682 | E40: Gold
B41: 7 | C41: Sam Miller | D41: 41289 | E41: Silver
B42: 8 | C42: Grace Taylor | D42: 38643 | E42: Silver
B43: 9 | C43: Rachel Brown | D43: 38334 | E43: Bronze
B44: 10 | C44: Carol Davis | D44: 36053 | E44: Bronze
B47: 💡 Automated Business Insights
B48: 🏆 Best Region: North with total sales of $288,583
B49: 💎 Most Profitable Product: Headphones (highest cumulative profit)
B50: 👤 Top Customer: Rachel Davis — contributed $59,482 in revenue
B51: 📉 Discount Impact: A 15% avg discount reduces profit by ~$37,298
B52: 📊 R² = 0.6239 — Sales is a strong predictor of Profit
B53: 📅 Seasonal Peak: Jan shows highest monthly sales
